Workbook
Name Advocacy: Sheet1!$F$2:$F$4
Name all_outcome_indicator: indicators!$O$2:$O$27
Name all_output_indicator: indicators!$P$2:$P$100
Name Child_Protection_Activity: '3. Sector_Child Protection'!$D$56:$D$85
Name Child_Protection_Output: '3. Sector_Child Protection'!$D$38:$D$52
Name Child_Sponsorship: Sheet1!$A$2:$A$4
Name climate_outcome_indicator: indicators!$I$2:$I$3
Name climate_output_indicator: indicators!$J$2:$J$10
Name community_output_indicator: indicators!$Q$2:$Q$13
Name Core_Alliance: Sheet1!$A$21:$A$28
Name Design_Type: Sheet1!$C$21:$C$23
Name Economic_Empowerment_Activity: '3. Sector_Economic Empowerment'!$D$57:$D$86
Name Economic_Empowerment_Output: '3. Sector_Economic Empowerment'!$D$39:$D$53
Name economy_outcome_indicator: indicators!$G$2:$G$7
Name economy_output_indicator: indicators!$H$2:$H$20
Name Education: Sheet1!$B$2:$B$7
Name Education_Activity: '3. Sector_Education'!$D$59:$D$88
Name education_outcome_indicator: indicators!$C$2:$C$8
Name Education_Output: '3. Sector_Education'!$D$41:$D$55
Name education_output_indicator: indicators!$D$2:$D$26
Name Environment: Sheet1!$G$2:$G$6
Name Health_Avtivity: '3. Sector_Health & Well-being'!$D$57:$D$86
Name health_outcome_indicator: indicators!$E$2:$E$4
Name health_output_indicator: indicators!$F$2:$F$39
Name Health_WellBeing: Table12[_03000_Health]
Name Health_WellBeing_Activity: '3. Sector_Health & Well-being'!$D$57:$D$86
Name Health_WellBeing_Output: '3. Sector_Health & Well-being'!$D$39:$D$53
Name Humanitarian_Assistance: Sheet1!$H$2:$H$8
Name humanitarian_outcome_indicator: indicators!$K$2:$K$2
Name humanitarian_output_indicator: indicators!$L$2:$L$14
Name Income_Generation: Sheet1!$D$2:$D$6
Name ITT_ChildProtection_OC_A: '3. Sector_Child Protection'!$A$32:$A$36
Name ITT_ChildProtection_OC_B: '3. Sector_Child Protection'!$B$32:$B$36
Name ITT_ChildProtection_OC_E: '3. Sector_Child Protection'!$E$32:$E$36
Name ITT_ChildProtection_OC_G: '3. Sector_Child Protection'!$G$32:$G$36
Name ITT_ChildProtection_OC_J: '3. Sector_Child Protection'!$J$32:$J$36
Name ITT_ChildProtection_OC_K: '3. Sector_Child Protection'!$K$32:$K$36
Name ITT_ChildProtection_OP_A: '3. Sector_Child Protection'!$A$38:$A$52
Name ITT_ChildProtection_OP_B: '3. Sector_Child Protection'!$B$38:$B$52
Name ITT_ChildProtection_OP_E: '3. Sector_Child Protection'!$E$38:$E$52
Name ITT_ChildProtection_OP_G: '3. Sector_Child Protection'!$G$38:$G$52
Name ITT_ChildProtection_OP_J: '3. Sector_Child Protection'!$J$38:$J$52
Name ITT_ChildProtection_OP_K: '3. Sector_Child Protection'!$K$38:$K$52
Name ITT_EconomicEmpowerment_OC_A: '3. Sector_Economic Empowerment'!$A$33:$A$37
Name ITT_EconomicEmpowerment_OC_B: '3. Sector_Economic Empowerment'!$B$33:$B$37
Name ITT_EconomicEmpowerment_OC_E: '3. Sector_Economic Empowerment'!$E$33:$E$37
Name ITT_EconomicEmpowerment_OC_G: '3. Sector_Economic Empowerment'!$G$33:$G$37
Name ITT_EconomicEmpowerment_OC_J: '3. Sector_Economic Empowerment'!$J$33:$J$37
Name ITT_EconomicEmpowerment_OC_K: '3. Sector_Economic Empowerment'!$K$33:$K$37
Name ITT_EconomicEmpowerment_OP_A: '3. Sector_Economic Empowerment'!$A$39:$A$53
Name ITT_EconomicEmpowerment_OP_B: '3. Sector_Economic Empowerment'!$B$39:$B$53
Name ITT_EconomicEmpowerment_OP_E: '3. Sector_Economic Empowerment'!$E$39:$E$53
Name ITT_EconomicEmpowerment_OP_G: '3. Sector_Economic Empowerment'!$G$39:$G$53
Name ITT_EconomicEmpowerment_OP_J: '3. Sector_Economic Empowerment'!$J$39:$J$53
Name ITT_EconomicEmpowerment_OP_K: '3. Sector_Economic Empowerment'!$K$39:$K$53
Name ITT_Education_OC_A: '3. Sector_Education'!$A$35:$A$39
Name ITT_Education_OC_B: '3. Sector_Education'!$B$35:$B$39
Name ITT_Education_OC_E: '3. Sector_Education'!$E$35:$E$39
Name ITT_Education_OC_G: '3. Sector_Education'!$G$35:$G$39
Name ITT_Education_OC_J: '3. Sector_Education'!$J$35:$J$39

Sheet Cover
B3: Project Proposal Form
B7: Country Name
B8: Project Name
B9: Project Type
B10: Design Type
B11: Prepared by | E11: (Name) | H11: (Position)
B12: Reviewed by | E12: (Name) | H12: (Position)
B13: Authorized by | E13: (Name) | H13: (Position)
B14: Submission Date | E14: MM-DD-YY
B17: Table of Contents
C19: 1. Project Overview
C21: 2. Community Assessment Result
D22: Basic Information of the Community
D23: Needs Assessment Result *Commencement Only
D24: Contextual Analysis
C26: 3. Sectoral Approach
D27: Project Overview
D28: Situation Analysis
D29: Project Scope
D30: Project Implementation Plan
C32: 4. Child Sponsorship Management (If applicable)
D33: Program Area Overview
D34: Sponsorship Program Operation Plan
D35: Risk Management Plan
C37: 5. Project Management Plan
D38: Network Management Plan
D39: Budget Management Plan
D40: Human Resource Management Plan
C42: (Annex) Indicator Tracking Tool

Sheet 1. Project Overview
A1: 1. Project Overview
A2: Category | B2: Description
A3: Target Area | B3: Target Area Name
B4: GPS coordinates of target area
B5: Distance from the Head Office
B6: Please put the map of the Target Area.
A7: Project Period (MM.YYYY~MM.YYYY) | D7: ~
A8: Project Budget (USD)
A9: Direct Participants | B9: Children | C9: Boy
C10: Girl
B11: Adults | C11: Male
C12: Female
A13: Indirect Participants | B13: Male
B14: Female
A15: Expected Outcome and Output | B15: Please share the overall logical framework of the project.

Sheet 2. Community Assessment Result
A1: 2. Community Assessment Result
A2: General Information of the Community
A3: Total Population | E3: =A5+B5+C5+E5+F5+G5+H5 -> 0
A4: Age 0-5 (Under 5) | B4: Ages 6-12 (Primary) | C4: Ages 13-18 (Secondary) | E4: Ages 19-24 (Youth) | F4: Ages 25-39 | G4: Ages 40-59 | H4: Ages Over 60 (Elderly)
A6: Number of Households | B6: Average Number of People per Household | C6: Distance to Nearest Market | E6: Average Household Income (USD) | F6: Race(s) / Tribe(s) / Ethnic Group(s) | G6: Prevailing Religion(s) | H6: Native Language(s)
A8: Need Assessment Result
A9: PAP Methodology | B9: Target Group / Respondents | C9: ► | D9: Assessment Findings
D10: Provide a concise summary of the key findings from the PAP. - Major issues - Community needs - Existing resources - Any notable patterns or gaps identified during the assessment
A15: Contextual Analysis
A16: Category | B16: Status | F16: Consideration
A17: Political Context | B17: Please provide information about the community situations based on the following categories: - Government structure - Political conflicts - Legal system - Others | F17: Please provide an overview of the relevant contextual factors that GN should consider when implementing the project.
A18: Social Context | B18: - Decision-making structure - Dominant religion (faith group) and their influence - Most vulnerable group - Others
A19: Economic Context | B19: - Major income source of households - Income level of the community people - Others (e.g., technology, etc.)
A20: Environmental Context | B20: - Climate change issues in the community - Most frequent natural disasters - Natural resources - Others (e.g., technology, etc.)

Sheet 3. Sector_Child Protection
A1: 3. Sectoral Approach_Child Protection
A2: Target Participants | C2: Children (Boy) | I2: Adults (Male)
C3: Children (Girl) | I3: Adults (Female)
A4: Key Statistics
A5: Birth Registration Rate | C5: Child Marriage Rate | E5: Median Age at First Marriage | F5: Adolescent Birth Rate | G5: Child Labor Rate | I5: Out of School Children Rate | K5: Prevalence of violence against child | M5: Existence of child abuse reporting and response system | O5: Remarks
A7: Data Source | C7: Please indicate the source of the statistics entered above, including the name of the source (e.g., national census, DHS/MICS, government or ministry report, GN community assessment), the reference year, and the geographic level of the data (national, provincial, district, or project community). Where figures come from different sources, please specify the source for each indicator.
A8: Situation Analysis
A9: Child Protection-related Status in the Community | C9: Please describe child protection related situations in the community and consider how they relate with the following sections. - Child protection-related situations in the community that requires GN's intervention - Contextual properties of the community and cross-cutting issues that GN should consider when implementing a sectoral approach.
A10: Problem Tree
A11: Effect | C11: Please put the image of the problem tree. (Insert > Pictures > This Device)
A12: Main Problem
A13: Causes
A14: Photos | C14: Please include photos that clearly show the current problem situation in the community.
A15: Case Story | C15: Please share a case story that illustrates the problem situation well.
A16: Objective Tree
A17: Ends | C17: Please put the image of objective tree. (Insert > Pictures > This Device)
A18: Objectives
A19: Means
A20: Alignment with Country MLTSP
A21: Related Programmatic Direction | C21: Strategic Objective
C23: Expected Outcome | I23: Related Outcome Indicator
A27: Project Result and M&E Framework
A28: Cross-cutting Issue | K28: Remarks
A29: Log Frame | E29: M&E Framework
A30: Objective | E30: Indicator | G30: Definition | I30: Unit | J30: Baseline | K30: Target | L30: Means of Verification | O30: Frequency of Data Collection
A31: Outcome
A32: 1
A33: 2
A34: 3
A35: 4
A36: 5
A37: Output
A38: 1.1 | D38: =A38&" "&B38 -> 1.1
A39: 1.2 | D39: =A39&" "&B39 -> 1.2
A40: 1.3 | D40: =A40&" "&B40 -> 1.3
A41: 2.1 | D41: =A41&" "&B41 -> 2.1
A42: 2.2 | D42: =A42&" "&B42 -> 2.2
A43: 2.3 | D43: =A43&" "&B43 -> 2.3
A44: 3.1 | D44: =A44&" "&B44 -> 3.1
A45: 3.2 | D45: =A45&" "&B45 -> 3.2
...

Sheet 3. Sector_Education
A1: 3. Sectoral Approach_Education
A2: Target Participants | C2: Children (Boy) | I2: Adults (Male)
C3: Children (Girl) | I3: Adults (Female)
A4: Key Statistics
A5: School System | C5: Number of School | E5: Enrolment Rate | F5: Attendance Rate | G5: Completion Rate | I5: Dropout Rate | K5: Student-Teacher Ratio | M5: Age Group | O5: Literacy Rate | P5: Numeracy Rate
A6: Nursery / Pre-school | M6: Children
A7: Primary School
A8: Secondary School | M8: Adult
A9: Tertiary
A10: Data Source | C10: Please indicate the source of the statistics entered above, including the name of the source (e.g., national census, DHS/MICS, government or ministry report, GN community assessment), the reference year, and the geographic level of the data (national, provincial, district, or project community). Where figures come from different sources, please specify the source for each indicator.
A11: Situation Analysis
A12: Education-related Status in the Community | C12: Please describe education-related situations within the community and consider how they relate with the following sections. - Education-related situation in the community that requires GN's intervention - Contextual properties of the community and cross-cutting issues that GN should consider when implementing a sectoral approach
A13: Problem Tree
A14: Effect | C14: Please put the image of the problem tree. (Insert > Pictures > This Device)
A15: Main Problem
A16: Causes
A17: Photos | C17: Please include photos that clearly show the current problem situation in the community.
A18: Case Story | C18: Please share a case story that illustrates the problem situation well.
A19: Objective Tree
A20: Ends | C20: Please put the image of objective tree. (Insert > Pictures > This Device)
A21: Objectives
A22: Means
A23: Alignment with Country MLTSP
A24: Related Programmatic Direction | C24: Strategic Objective
C26: Expected Outcome | I26: Related Outcome Indicator
A30: Project Result and M&E Framework
A31: Cross-cutting Issue | K31: Remarks
A32: Log Frame | E32: M&E Framework
A33: Objective | E33: Indicator | G33: Definition | I33: Unit | J33: Baseline | K33: Target | L33: Means of Verification | O33: Frequency of Data Collection
A34: Outcome
A35: 1
A36: 2
A37: 3
A38: 4
A39: 5
A40: Output
A41: 1.1 | D41: =A41&" "&B41 -> 1.1
A42: 1.2 | D42: =A42&" "&B42 -> 1.2
A43: 1.3 | D43: =A43&" "&B43 -> 1.3
A44: 2.1 | D44: =A44&" "&B44 -> 2.1
...

Sheet 3. Sector_Health & Well-being
A1: 3. Sectoral Approach_Health and Well-being
A2: Target Participants | C2: Children (Boy) | I2: Adults (Male)
C3: Children (Girl) | I3: Adults (Female)
A4: Key Statistics
A5: Health | K5: WASH | O5: Remarks
A6: Access Rate to the Basic Health Services | C6: No. of Equipped Health Facility | E6: Under 5 Mortality Rate | F6: Skilled Birth Attendance Rate | G6: Immunization Coverage Rate (Under 5) | I6: Leading Causes of Morbidity & Mortality | K6: Access Rate to Safe Drinking Water | M6: Access Rate to Basic Sanitation
A8: Data Source | C8: Please indicate the source of the statistics entered above, including the name of the source (e.g., national census, DHS/MICS, government or ministry report, GN community assessment), the reference year, and the geographic level of the data (national, provincial, district, or project community). Where figures come from different sources, please specify the source for each indicator.
A9: Situation Analysis
A10: Health & Well-being-related Status in the Community | C10: Please describe the Health & Well-being situation in the community, with consideration of the following: - Health & Well-being conditions that require GN's intervention - Contextual factors and cross-cutting issues GN should consider when implementing a sectoral approach
A11: Problem Tree
A12: Effect | C12: Please put the image of the problem tree. (Insert > Pictures > This Device)
A13: Main Problem
A14: Causes
A15: Photos | C15: Please include photos that clearly show the current problem situation in the community.
A16: Case Story | C16: Please share a case story that illustrates the problem situation well.
A17: Objective Tree
A18: Ends | C18: Please put the image of objective tree. (Insert > Pictures > This Device)
A19: Objectives
A20: Means
A21: Alignment with Country MLTSP
A22: Related Programmatic Direction | C22: Strategic Objective
C24: Expected Outcome | I24: Related Outcome Indicator
A28: Project Result and M&E Framework
A29: Cross-cutting Issue | K29: Remarks
A30: Log Frame | E30: M&E Framework
A31: Objective | E31: Indicator | G31: Definition | I31: Unit | J31: Baseline | K31: Target | L31: Means of Verification | O31: Frequency of Data Collection
A32: Outcome
A33: 1
A34: 2
A35: 3
A36: 4
A37: 5
A38: Output
A39: 1.1 | D39: =A39&" "&B39 -> 1.1
A40: 1.2 | D40: =A40&" "&B40 -> 1.2
A41: 1.3 | D41: =A41&" "&B41 -> 1.3
A42: 2.1 | D42: =A42&" "&B42 -> 2.1
A43: 2.2 | D43: =A43&" "&B43 -> 2.2
A44: 2.3 | D44: =A44&" "&B44 -> 2.3
A45: 3.1 | D45: =A45&" "&B45 -> 3.1
...

Sheet 3. Sector_Economic Empowerment
A1: 3. Sectoral Approach_Economic Empowerment
A2: Target Participants | C2: Children (Boy) | I2: Adults (Male)
C3: Children (Girl) | I3: Adults (Female)
A4: Key Statistics
C5: Labor Force Participation Rate | E5: Unemployment Rate | F5: Average Monthly Income of Household | G5: Primary Source of Income | M5: Access Rate to Financial Services | O5: Remarks
A6: Male
A7: Female
A8: Data Source | C8: Please indicate the source of the statistics entered above, including the name of the source (e.g., national census, DHS/MICS, government or ministry report, GN community assessment), the reference year, and the geographic level of the data (national, provincial, district, or project community). Where figures come from different sources, please specify the source for each indicator.
A9: Situation Analysis
A10: Economic Empowerment-related Status in the Community | C10: Please describe Economic Empowerment-related situations in the community and consider how they relate with the following sections. - Economic Empowerment related situation in the community that requires GN's intervention - Contextual properties of the community and cross-cutting issues that GN should consider when implementing a sectoral approach.
A11: Problem Tree
A12: Effect | C12: Please put the image of the problem tree. (Insert > Pictures > This Device)
A13: Main Problem
A14: Causes
A15: Photos | C15: Please include photos that clearly show the current problem situation in the community.
A16: Case Story | C16: Please share a case story that illustrates the problem situation well.
A17: Objective Tree
A18: Ends | C18: Please put the image of objective tree. (Insert > Pictures > This Device)
A19: Objectives
A20: Means
A21: Alignment with Country MLTSP
A22: Related Programmatic Direction | C22: Strategic Objective
C24: Expected Outcome | I24: Related Outcome Indicator
A28: Project Result and M&E Framework
A29: Cross-cutting Issue | K29: Remarks
A30: Log Frame | E30: M&E Framework
A31: Objective | E31: Indicator | G31: Definition | I31: Unit | J31: Baseline | K31: Target | L31: Means of Verification | O31: Frequency of Data Collection
A32: Outcome
A33: 1
A34: 2
A35: 3
A36: 4
A37: 5
A38: Output
A39: 1.1 | D39: =A39&" "&B39 -> 1.1
A40: 1.2 | D40: =A40&" "&B40 -> 1.2
A41: 1.3 | D41: =A41&" "&B41 -> 1.3
A42: 2.1 | D42: =A42&" "&B42 -> 2.1
A43: 2.2 | D43: =A43&" "&B43 -> 2.2
A44: 2.3 | D44: =A44&" "&B44 -> 2.3
...

Sheet 3. Sector_Others
A1: 3. Sectoral Approach_Others
A2: Target Participants | C2: Children (Boy) | I2: Adults (Male)
C3: Children (Girl) | I3: Adults (Female)
A4: Key Statistics
A7: Data Source | C7: Please indicate the source of the statistics entered above, including the name of the source (e.g., national census, DHS/MICS, government or ministry report, GN community assessment), the reference year, and the geographic level of the data (national, provincial, district, or project community). Where figures come from different sources, please specify the source for each indicator.
A8: Situation Analysis
A9: Sector-specific Status in the Community | C9: This section is for sectors not covered under Education, Health & Well-being, Economic Empowerment, or Child Protection (e.g., Climate Change, Humanitarian Assistance). Clearly specify the sector being addressed (e.g., Climate Change, Humanitarian Assistance, Environment, Psychosocial Support, etc.) and describe the sector-specific situation in the community - Key issues that require GN's intervention in this sector; - Contextual properties of the community and cross-cutting issues that GN should consider when implementing a sectoral approach.
A10: Problem Tree
A11: Effect | C11: Please put the image of the problem tree. (Insert > Pictures > This Device)
A12: Main Problem
A13: Causes
A14: Photos | C14: Please include photos that clearly show the current problem situation in the community.
A15: Case Story | C15: Please share a case story that illustrates the problem situation well.
A16: Objective Tree
A17: Ends | C17: Please put the image of objective tree. (Insert > Pictures > This Device)
A18: Objectives
A19: Means
A20: Alignment with Country MLTSP
A21: Related Programmatic Direction | C21: Strategic Objective
C23: Expected Outcome | I23: Related Outcome Indicator
A27: Project Result and M&E Framework
A28: Cross-cutting Issue | K28: Remarks
A29: Log Frame | E29: M&E Framework
A30: Objective | E30: Indicator | G30: Definition | I30: Unit | J30: Baseline | K30: Target | L30: Means of Verification | O30: Frequency of Data Collection
A31: Outcome
A32: 1
A33: 2
A34: 3
A35: 4
A36: 5
A37: Output
A38: 1.1 | D38: =A38&" "&B38 -> 1.1
A39: 1.2 | D39: =A39&" "&B39 -> 1.2
A40: 1.3 | D40: =A40&" "&B40 -> 1.3
A41: 2.1 | D41: =A41&" "&B41 -> 2.1
A42: 2.2 | D42: =A42&" "&B42 -> 2.2
A43: 2.3 | D43: =A43&" "&B43 -> 2.3
A44: 3.1 | D44: =A44&" "&B44 -> 3.1
A45: 3.2 | D45: =A45&" "&B45 -> 3.2
A46: 3.3 | D46: =A46&" "&B46 -> 3.3
...

Sheet 4. Child Sponsorship Management
A1: 4. Child Sponsorship Management (If applicable)
A2: Program Area Overview
A3: Category | C3: Description
A4: Possibility and Ground of Child Sponsorship Program | C4: Please describe the possibility and ground of the child sponsorship program, considering the following points. - Validity of area selection (socio-economic vulnerability; high concentration of children in need of protection) - Scale of eligible children (at least 1,000 children) - No overlap with other NGOs (area not currently covered by other NGO support)
A5: Selection Criteria for Children | C5: Please describe the criteria used to select sponsored children, referring to the guidelines. - Age range and priority given to vulnerable children - Number of children selected per household - Length of residence in the target area - Children not already sponsored by GN or another organization
A6: Community Participation | C6: Please describe the level of participation and cooperation expected from the community. - Roles of sponsored children (CIF, APR, ACL, health check-up, letter writing) and participation in community project activities - Roles of parents / guardians (supporting the child's participation, using the support for its intended purpose, joining the parents association and volunteer network, reporting changes in family circumstances) - Cooperation of local government, schools and community leaders
A7: Positive and Negative Factors | C7: Please describe the conditions that may help or hinder the program, and how the project will respond. - Positive factors (e.g., cooperation of local government and schools, level of need in the community) - Negative factors (e.g., travel time to households, language differences, early marriage) and planned mitigation measures
A8: Sponsored Children by Year
A9: Category | B9: Sponsor | C9: Existing | D9: Year 1 | G9: Year 2 | J9: Year 3 | M9: Year 4 | P9: Year 5
D10: New | E10: Drop-out | F10: Total | G10: New | H10: Drop-out | I10: Total | J10: New | K10: Drop-out | L10: Total | M10: New | N10: Drop-out | O10: Total | P10: New | Q10: Drop-out | R10: Total
A11: Core Alliance Country | B11: Korea | F11: =C11+D11-E11 -> 0 | I11: =F11+G11-H11 -> 0 | L11: =I11+J11-K11 -> 0 | O11: =L11+M11-N11 -> 0 | R11: =O11+P11-Q11 -> 0
B12: USA | F12: =C12+D12-E12 -> 0 | I12: =F12+G12-H12 -> 0 | L12: =I12+J12-K12 -> 0 | O12: =L12+M12-N12 -> 0 | R12: =O12+P12-Q12 -> 0
B13: Japan | F13: =C13+D13-E13 -> 0 | I13: =F13+G13-H13 -> 0 | L13: =I13+J13-K13 -> 0 | O13: =L13+M13-N13 -> 0 | R13: =O13+P13-Q13 -> 0
B14: Canada | F14: =C14+D14-E14 -> 0 | I14: =F14+G14-H14 -> 0 | L14: =I14+J14-K14 -> 0 | O14: =L14+M14-N14 -> 0 | R14: =O14+P14-Q14 -> 0
B15: Australia | F15: =C15+D15-E15 -> 0 | I15: =F15+G15-H15 -> 0 | L15: =I15+J15-K15 -> 0 | O15: =L15+M15-N15 -> 0 | R15: =O15+P15-Q15 -> 0
B16: UK | F16: =C16+D16-E16 -> 0 | I16: =F16+G16-H16 -> 0 | L16: =I16+J16-K16 -> 0 | O16: =L16+M16-N16 -> 0 | R16: =O16+P16-Q16 -> 0
B17: Taiwan | F17: =C17+D17-E17 -> 0 | I17: =F17+G17-H17 -> 0 | L17: =I17+J17-K17 -> 0 | O17: =L17+M17-N17 -> 0 | R17: =O17+P17-Q17 -> 0
A18: Sub total | C18: =SUM(C11:C17) -> 0 | D18: =SUM(D11:D17) -> 0 | E18: =SUM(E11:E17) -> 0 | F18: =SUM(F11:F17) -> 0 | G18: =SUM(G11:G17) -> 0 | H18: =SUM(H11:H17) -> 0 | I18: =SUM(I11:I17) -> 0 | J18: =SUM(J11:J17) -> 0 | ... R18: =SUM(R11:R17) -> 0
A19: Local | F19: =C19+D19-E19 -> 0 | I19: =F19+G19-H19 -> 0 | L19: =I19+J19-K19 -> 0 | O19: =L19+M19-N19 -> 0 | R19: =O19+P19-Q19 -> 0
A20: Total | C20: =C18+C19 -> 0 | D20: =D18+D19 -> 0 | E20: =E18+E19 -> 0 | F20: =F18+F19 -> 0 | G20: =G18+G19 -> 0 | H20: =H18+H19 -> 0 | I20: =I18+I19 -> 0 | J20: =J18+J19 -> 0 | ... R20: =R18+R19 -> 0
A21: Five-Year Program Plan
A22: Child Sponsorship Program
A23: Classification | B23: Service | C23: Target | E23: Standard | G23: Basis of Calculation | J23: Unit | K23: Unit cost ($) | L23: Total | M23: FY1 | N23: FY2 | O23: FY3 | P23: FY4 | Q23: FY5 | R23: Total
A24: Child Sponsorship Management | B24: Child Management | C24: All sponsored children | E24: 3 times / year | L24: =J24*K24 -> 0 | R24: =SUM(M24:Q24) -> 0
A25: Child Protection | B25: Child Rights Campaign | E25: - | L25: =J25*K25 -> 0 | R25: =SUM(M25:Q25) -> 0
A26: Education | B26: Financial / Material Support | E26: - | L26: =J26*K26 -> 0 | R26: =SUM(M26:Q26) -> 0
B27: Alternative (Non-formal) Education Support | C27: All sponsored children not in school | E27: 1 time / child / year | L27: =J27*K27 -> 0 | R27: =SUM(M27:Q27) -> 0
A28: Health & Well-being | B28: Health Check-up | C28: All sponsored children | E28: - | L28: =J28*K28 -> 0 | R28: =SUM(M28:Q28) -> 0
B29: Nutrition Support | C29: All sponsored children with severe malnutrition | E29: 100% of target children | L29: =J29*K29 -> 0 | R29: =SUM(M29:Q29) -> 0
B30: WASH Education | C30: All sponsored children | E30: - | L30: =J30*K30 -> 0 | R30: =SUM(M30:Q30) -> 0
A31: Others | L31: =J31*K31 -> 0 | R31: =SUM(M31:Q31) -> 0
L32: =J32*K32 -> 0 | R32: =SUM(M32:Q32) -> 0
L33: =J33*K33 -> 0 | R33: =SUM(M33:Q33) -> 0
A34: Total | L34: =SUM(L24:L33) -> 0 | M34: =SUM(M24:M33) -> 0 | N34: =SUM(N24:N33) -> 0 | O34: =SUM(O24:O33) -> 0 | P34: =SUM(P24:P33) -> 0 | Q34: =SUM(Q24:Q33) -> 0 | R34: =SUM(R24:R33) -> 0
A35: Monitoring & Evaluation
A36: Service | B36: Frequency | C36: Method | F36: Basis of Calculation | J36: Unit | K36: Unit cost ($) | L36: Total | M36: FY1 | N36: FY2 | O36: FY3 | P36: FY4 | Q36: FY5 | R36: Total
A37: CIF | L37: =J37*K37 -> 0 | R37: =SUM(M37:Q37) -> 0
A38: APR | L38: =J38*K38 -> 0 | R38: =SUM(M38:Q38) -> 0
A39: ACL | L39: =J39*K39 -> 0 | R39: =SUM(M39:Q39) -> 0
A40: Others | L40: =J40*K40 -> 0 | R40: =SUM(M40:Q40) -> 0
...

Sheet 5. Project Management Plan
A1: 5. Project Management
A2: Network Management
A3: Community Engagement Plan
A4: Related indicator | D4: Target | E4: Description
E5: Name of Committee | F5: No. of Committee Members | G5: Related sector | H5: Key roles
A6: No. of Committees
A7: No. of Sub-Committees
A8: No. of Committee Members | C8: Male
C9: Female
A10: Committee Operation Plan | E10: Please describe the committee organization plan including the belows.: • Membership criteria — who is eligible to join (e.g., religious leaders, village leaders, women leaders, youth representatives, school principals, village representative groups); • Representation & inclusion — how gender balance and the participation of vulnerable or marginalised groups will be secured; • Selection process — how members are nominated or elected, and how transparency is ensured; • Term & turnover — length of service and how replacement members will be recruited.
A11: No. of training sessions for committee or sub-committee members | E11: Please describe the capacity-building plan for committee and sub-committee members referring to the guidelines.
A12: No. of meetings held by committees and sub-committees | E12: Please describe the operation and participation plan for committees and sub-committees referring to the guidelines.
A13: No. of children’s, teens’ or youth clubs supported by GN | E13: Please describe the plan for children’s, teens’ or youth clubs supported by the project referring to the guidelines.
A14: No. of members in children’s, teens’ or youth clubs supported by GN
A15: Stakeholder Engagement & Collaboration Plan
A16: Stakeholder Group | C16: Attitude toward GN Projects | D16: Area of Technical Expertise | E16: Coverage in Project Area | F16: Partnership & Networking Plan
A20: Risk Management
A21: Risk | D21: Mitigation Plan
A22: Please provide the identified risks in the planned sectoral approach. | D22: Please describe the plan on how you will mitigate the identified risks.
A25: Evaluation Plan
A26: Please describe the plan for assessing Outcome-level results across the project cycle, including: - Evaluation approach — whether assessments will be conducted internally (e.g., pre/post surveys by project staff) or in partnership with an external agency (e.g., consultant engagement, development of standardized assessment tools); - Review cycle — frequency and timing of Outcome indicator tracking throughout the project period; - Other considerations — any additional elements relevant to the evaluation approach, such as data quality assurance measures, stakeholder involvement in the evaluation process, or plans for disseminating findings.
A27: Sustainability Plan
A28: Category | C28: Description
A29: Financial Sustainability | C29: Please describe how the project will secure continued funding and resources beyond the project period. This includes plans for local budget integration, strategies to reduce external donor dependency, and any income-generating mechanisms linked to the project.
A30: Transition & Local Ownership Plan | C30: Please describe how project responsibilities and operations will be gradually transferred to local governments, community organizations, or other local stakeholders. Include a phased handover timeline, capacity-building measures for local actors, and how community ownership will be ensured to sustain project outcomes beyond GN's involvement.
A31: Budget Management Plan
A32: Income Plan
A33: Related Support Country | F33: Remarks
A34: Category / Project Year | C34: Year 1 | D34: Year 2 | E34: Year 3 | F34: Year 4 | G34: Year 5 | H34: Total | I34: %
A35: GPC Subsidy | C35: =SUM(C36:C39) -> 0 | D35: =SUM(D36:D39) -> 0 | E35: =SUM(E36:E39) -> 0 | F35: =SUM(F36:F39) -> 0 | G35: =SUM(G36:G39) -> 0 | H35: =SUM(C35:G35) -> 0 | I35: =IFERROR(H35/H47,"")
A36: Child Sponsorship Fund | H36: =SUM(C36:G36) -> 0 | I36: =IFERROR(H36/H47,"")
A37: Project Sponsorship Fund | H37: =SUM(C37:G37) -> 0 | I37: =IFERROR(H37/H47,"")
A38: Designated | H38: =SUM(C38:G38) -> 0 | I38: =IFERROR(H38/H47,"")
A39: Government | H39: =SUM(C39:G39) -> 0 | I39: =IFERROR(H39/H47,"")
A40: Local Income | C40: =SUM(C41:C46) -> 0 | D40: =SUM(D41:D46) -> 0 | E40: =SUM(E41:E46) -> 0 | F40: =SUM(F41:F46) -> 0 | G40: =SUM(G41:G46) -> 0 | H40: =SUM(C40:G40) -> 0 | I40: =IFERROR(H40/H47,"")
A41: General (regular sponsorship) | H41: =SUM(C41:G41) -> 0 | I41: =IFERROR(H41/H47,"")
A42: Designated Fund (irregular; one-time donation) | H42: =SUM(C42:G42) -> 0 | I42: =IFERROR(H42/H47,"")
A43: Government Fund (national/local government) | H43: =SUM(C43:G43) -> 0 | I43: =IFERROR(H43/H47,"")
A44: International Organization | H44: =SUM(C44:G44) -> 0 | I44: =IFERROR(H44/H47,"")
A45: Gift in Kinds | H45: =SUM(C45:G45) -> 0 | I45: =IFERROR(H45/H47,"")
...

Sheet (Annex) Indicator Tracking Tool
A1: Indicator Tracking Tool
A3: Sector | B3: Level | C3: No. | D3: Objective | E3: Indicator | F3: Definition / Calculation Basis | G3: Baseline | H3: Target | I3: Y1 | O3: Y2 | U3: Y3 | AA3: Y4 | AG3: Y5
I4: Q1 | J4: Q2 | K4: Q3 | L4: Q4 | M4: % Achieved | N4: Comments on Variance | O4: Q1 | P4: Q2 | Q4: Q3 | R4: Q4 | S4: % Achieved | T4: Comments on Variance | U4: Q1 | V4: Q2 | W4: Q3 | X4: Q4 | Y4: % Achieved | Z4: Comments on Variance | AA4: Q1 | AB4: Q2 | AC4: Q3 | AD4: Q4 | AE4: % Achieved | AF4: Comments on Variance | AG4: Q1 | AH4: Q2 | AI4: Q3 | AJ4: Q4 | AK4: % Achieved | AL4: Comments on Variance
A5: Child Protection | B5: Outcome | C5: =IFERROR(IF(INDEX(ITT_ChildProtection_OC_A,MATCH("1",ITT_ChildProtection_OC_A,0))="","",INDEX(ITT_ChildProtection_OC_A,MATCH("1",ITT_ChildProtection_OC_A,0))),"") -> 1 | D5: =IFERROR(IF(INDEX(ITT_ChildProtection_OC_B,MATCH("1",ITT_ChildProtection_OC_A,0))="","",INDEX(ITT_ChildProtection_OC_B,MATCH("1",ITT_ChildProtection_OC_A,0))),"") | E5: =IFERROR(IF(INDEX(ITT_ChildProtection_OC_E,MATCH("1",ITT_ChildProtection_OC_A,0))="","",INDEX(ITT_ChildProtection_OC_E,MATCH("1",ITT_ChildProtection_OC_A,0))),"") | F5: =IFERROR(IF(INDEX(ITT_ChildProtection_OC_G,MATCH("1",ITT_ChildProtection_OC_A,0))="","",INDEX(ITT_ChildProtection_OC_G,MATCH("1",ITT_ChildProtection_OC_A,0))),"") | G5: =IFERROR(IF(INDEX(ITT_ChildProtection_OC_J,MATCH("1",ITT_ChildProtection_OC_A,0))="","",INDEX(ITT_ChildProtection_OC_J,MATCH("1",ITT_ChildProtection_OC_A,0))),"") | H5: =IFERROR(IF(INDEX(ITT_ChildProtection_OC_K,MATCH("1",ITT_ChildProtection_OC_A,0))="","",INDEX(ITT_ChildProtection_OC_K,MATCH("1",ITT_ChildProtection_OC_A,0))),"") | M5: =IF(OR(L5="",$G5="",$H5=""),"",IF($H5-$G5=0,"",(L5-$G5)/($H5-$G5))) | S5: =IF(OR(R5="",$G5="",$H5=""),"",IF($H5-$G5=0,"",(R5-$G5)/($H5-$G5))) | Y5: =IF(OR(X5="",$G5="",$H5=""),"",IF($H5-$G5=0,"",(X5-$G5)/($H5-$G5))) | AE5: =IF(OR(AD5="",$G5="",$H5=""),"",IF($H5-$G5=0,"",(AD5-$G5)/($H5-$G5))) | AK5: =IF(OR(AJ5="",$G5="",$H5=""),"",IF($H5-$G5=0,"",(AJ5-$G5)/($H5-$G5)))
C6: =IFERROR(IF(INDEX(ITT_ChildProtection_OC_A,MATCH("2",ITT_ChildProtection_OC_A,0))="","",INDEX(ITT_ChildProtection_OC_A,MATCH("2",ITT_ChildProtection_OC_A,0))),"") -> 2 | D6: =IFERROR(IF(INDEX(ITT_ChildProtection_OC_B,MATCH("2",ITT_ChildProtection_OC_A,0))="","",INDEX(ITT_ChildProtection_OC_B,MATCH("2",ITT_ChildProtection_OC_A,0))),"") | E6: =IFERROR(IF(INDEX(ITT_ChildProtection_OC_E,MATCH("2",ITT_ChildProtection_OC_A,0))="","",INDEX(ITT_ChildProtection_OC_E,MATCH("2",ITT_ChildProtection_OC_A,0))),"") | F6: =IFERROR(IF(INDEX(ITT_ChildProtection_OC_G,MATCH("2",ITT_ChildProtection_OC_A,0))="","",INDEX(ITT_ChildProtection_OC_G,MATCH("2",ITT_ChildProtection_OC_A,0))),"") | G6: =IFERROR(IF(INDEX(ITT_ChildProtection_OC_J,MATCH("2",ITT_ChildProtection_OC_A,0))="","",INDEX(ITT_ChildProtection_OC_J,MATCH("2",ITT_ChildProtection_OC_A,0))),"") | H6: =IFERROR(IF(INDEX(ITT_ChildProtection_OC_K,MATCH("2",ITT_ChildProtection_OC_A,0))="","",INDEX(ITT_ChildProtection_OC_K,MATCH("2",ITT_ChildProtection_OC_A,0))),"") | M6: =IF(OR(L6="",$G6="",$H6=""),"",IF($H6-$G6=0,"",(L6-$G6)/($H6-$G6))) | S6: =IF(OR(R6="",$G6="",$H6=""),"",IF($H6-$G6=0,"",(R6-$G6)/($H6-$G6))) | Y6: =IF(OR(X6="",$G6="",$H6=""),"",IF($H6-$G6=0,"",(X6-$G6)/($H6-$G6))) | AE6: =IF(OR(AD6="",$G6="",$H6=""),"",IF($H6-$G6=0,"",(AD6-$G6)/($H6-$G6))) | AK6: =IF(OR(AJ6="",$G6="",$H6=""),"",IF($H6-$G6=0,"",(AJ6-$G6)/($H6-$G6)))
C7: =IFERROR(IF(INDEX(ITT_ChildProtection_OC_A,MATCH("3",ITT_ChildProtection_OC_A,0))="","",INDEX(ITT_ChildProtection_OC_A,MATCH("3",ITT_ChildProtection_OC_A,0))),"") -> 3 | D7: =IFERROR(IF(INDEX(ITT_ChildProtection_OC_B,MATCH("3",ITT_ChildProtection_OC_A,0))="","",INDEX(ITT_ChildProtection_OC_B,MATCH("3",ITT_ChildProtection_OC_A,0))),"") | E7: =IFERROR(IF(INDEX(ITT_ChildProtection_OC_E,MATCH("3",ITT_ChildProtection_OC_A,0))="","",INDEX(ITT_ChildProtection_OC_E,MATCH("3",ITT_ChildProtection_OC_A,0))),"") | F7: =IFERROR(IF(INDEX(ITT_ChildProtection_OC_G,MATCH("3",ITT_ChildProtection_OC_A,0))="","",INDEX(ITT_ChildProtection_OC_G,MATCH("3",ITT_ChildProtection_OC_A,0))),"") | G7: =IFERROR(IF(INDEX(ITT_ChildProtection_OC_J,MATCH("3",ITT_ChildProtection_OC_A,0))="","",INDEX(ITT_ChildProtection_OC_J,MATCH("3",ITT_ChildProtection_OC_A,0))),"") | H7: =IFERROR(IF(INDEX(ITT_ChildProtection_OC_K,MATCH("3",ITT_ChildProtection_OC_A,0))="","",INDEX(ITT_ChildProtection_OC_K,MATCH("3",ITT_ChildProtection_OC_A,0))),"") | M7: =IF(OR(L7="",$G7="",$H7=""),"",IF($H7-$G7=0,"",(L7-$G7)/($H7-$G7))) | S7: =IF(OR(R7="",$G7="",$H7=""),"",IF($H7-$G7=0,"",(R7-$G7)/($H7-$G7))) | Y7: =IF(OR(X7="",$G7="",$H7=""),"",IF($H7-$G7=0,"",(X7-$G7)/($H7-$G7))) | AE7: =IF(OR(AD7="",$G7="",$H7=""),"",IF($H7-$G7=0,"",(AD7-$G7)/($H7-$G7))) | AK7: =IF(OR(AJ7="",$G7="",$H7=""),"",IF($H7-$G7=0,"",(AJ7-$G7)/($H7-$G7)))
C8: =IFERROR(IF(INDEX(ITT_ChildProtection_OC_A,MATCH("4",ITT_ChildProtection_OC_A,0))="","",INDEX(ITT_ChildProtection_OC_A,MATCH("4",ITT_ChildProtection_OC_A,0))),"") -> 4 | D8: =IFERROR(IF(INDEX(ITT_ChildProtection_OC_B,MATCH("4",ITT_ChildProtection_OC_A,0))="","",INDEX(ITT_ChildProtection_OC_B,MATCH("4",ITT_ChildProtection_OC_A,0))),"") | E8: =IFERROR(IF(INDEX(ITT_ChildProtection_OC_E,MATCH("4",ITT_ChildProtection_OC_A,0))="","",INDEX(ITT_ChildProtection_OC_E,MATCH("4",ITT_ChildProtection_OC_A,0))),"") | F8: =IFERROR(IF(INDEX(ITT_ChildProtection_OC_G,MATCH("4",ITT_ChildProtection_OC_A,0))="","",INDEX(ITT_ChildProtection_OC_G,MATCH("4",ITT_ChildProtection_OC_A,0))),"") | G8: =IFERROR(IF(INDEX(ITT_ChildProtection_OC_J,MATCH("4",ITT_ChildProtection_OC_A,0))="","",INDEX(ITT_ChildProtection_OC_J,MATCH("4",ITT_ChildProtection_OC_A,0))),"") | H8: =IFERROR(IF(INDEX(ITT_ChildProtection_OC_K,MATCH("4",ITT_ChildProtection_OC_A,0))="","",INDEX(ITT_ChildProtection_OC_K,MATCH("4",ITT_ChildProtection_OC_A,0))),"") | M8: =IF(OR(L8="",$G8="",$H8=""),"",IF($H8-$G8=0,"",(L8-$G8)/($H8-$G8))) | S8: =IF(OR(R8="",$G8="",$H8=""),"",IF($H8-$G8=0,"",(R8-$G8)/($H8-$G8))) | Y8: =IF(OR(X8="",$G8="",$H8=""),"",IF($H8-$G8=0,"",(X8-$G8)/($H8-$G8))) | AE8: =IF(OR(AD8="",$G8="",$H8=""),"",IF($H8-$G8=0,"",(AD8-$G8)/($H8-$G8))) | AK8: =IF(OR(AJ8="",$G8="",$H8=""),"",IF($H8-$G8=0,"",(AJ8-$G8)/($H8-$G8)))
C9: =IFERROR(IF(INDEX(ITT_ChildProtection_OC_A,MATCH("5",ITT_ChildProtection_OC_A,0))="","",INDEX(ITT_ChildProtection_OC_A,MATCH("5",ITT_ChildProtection_OC_A,0))),"") -> 5 | D9: =IFERROR(IF(INDEX(ITT_ChildProtection_OC_B,MATCH("5",ITT_ChildProtection_OC_A,0))="","",INDEX(ITT_ChildProtection_OC_B,MATCH("5",ITT_ChildProtection_OC_A,0))),"") | E9: =IFERROR(IF(INDEX(ITT_ChildProtection_OC_E,MATCH("5",ITT_ChildProtection_OC_A,0))="","",INDEX(ITT_ChildProtection_OC_E,MATCH("5",ITT_ChildProtection_OC_A,0))),"") | F9: =IFERROR(IF(INDEX(ITT_ChildProtection_OC_G,MATCH("5",ITT_ChildProtection_OC_A,0))="","",INDEX(ITT_ChildProtection_OC_G,MATCH("5",ITT_ChildProtection_OC_A,0))),"") | G9: =IFERROR(IF(INDEX(ITT_ChildProtection_OC_J,MATCH("5",ITT_ChildProtection_OC_A,0))="","",INDEX(ITT_ChildProtection_OC_J,MATCH("5",ITT_ChildProtection_OC_A,0))),"") | H9: =IFERROR(IF(INDEX(ITT_ChildProtection_OC_K,MATCH("5",ITT_ChildProtection_OC_A,0))="","",INDEX(ITT_ChildProtection_OC_K,MATCH("5",ITT_ChildProtection_OC_A,0))),"") | M9: =IF(OR(L9="",$G9="",$H9=""),"",IF($H9-$G9=0,"",(L9-$G9)/($H9-$G9))) | S9: =IF(OR(R9="",$G9="",$H9=""),"",IF($H9-$G9=0,"",(R9-$G9)/($H9-$G9))) | Y9: =IF(OR(X9="",$G9="",$H9=""),"",IF($H9-$G9=0,"",(X9-$G9)/($H9-$G9))) | AE9: =IF(OR(AD9="",$G9="",$H9=""),"",IF($H9-$G9=0,"",(AD9-$G9)/($H9-$G9))) | AK9: =IF(OR(AJ9="",$G9="",$H9=""),"",IF($H9-$G9=0,"",(AJ9-$G9)/($H9-$G9)))
B10: Output | C10: =IFERROR(IF(INDEX(ITT_ChildProtection_OP_A,MATCH("1.1",ITT_ChildProtection_OP_A,0))="","",INDEX(ITT_ChildProtection_OP_A,MATCH("1.1",ITT_ChildProtection_OP_A,0))),"") -> 1.1 | D10: =IFERROR(IF(INDEX(ITT_ChildProtection_OP_B,MATCH("1.1",ITT_ChildProtection_OP_A,0))="","",INDEX(ITT_ChildProtection_OP_B,MATCH("1.1",ITT_ChildProtection_OP_A,0))),"") | E10: =IFERROR(IF(INDEX(ITT_ChildProtection_OP_E,MATCH("1.1",ITT_ChildProtection_OP_A,0))="","",INDEX(ITT_ChildProtection_OP_E,MATCH("1.1",ITT_ChildProtection_OP_A,0))),"") | F10: =IFERROR(IF(INDEX(ITT_ChildProtection_OP_G,MATCH("1.1",ITT_ChildProtection_OP_A,0))="","",INDEX(ITT_ChildProtection_OP_G,MATCH("1.1",ITT_ChildProtection_OP_A,0))),"") | G10: =IFERROR(IF(INDEX(ITT_ChildProtection_OP_J,MATCH("1.1",ITT_ChildProtection_OP_A,0))="","",INDEX(ITT_ChildProtection_OP_J,MATCH("1.1",ITT_ChildProtection_OP_A,0))),"") | H10: =IFERROR(IF(INDEX(ITT_ChildProtection_OP_K,MATCH("1.1",ITT_ChildProtection_OP_A,0))="","",INDEX(ITT_ChildProtection_OP_K,MATCH("1.1",ITT_ChildProtection_OP_A,0))),"") | M10: =IF(OR(L10="",$G10="",$H10=""),"",IF($H10-$G10=0,"",(L10-$G10)/($H10-$G10))) | S10: =IF(OR(R10="",$G10="",$H10=""),"",IF($H10-$G10=0,"",(R10-$G10)/($H10-$G10))) | Y10: =IF(OR(X10="",$G10="",$H10=""),"",IF($H10-$G10=0,"",(X10-$G10)/($H10-$G10))) | AE10: =IF(OR(AD10="",$G10="",$H10=""),"",IF($H10-$G10=0,"",(AD10-$G10)/($H10-$G10))) | AK10: =IF(OR(AJ10="",$G10="",$H10=""),"",IF($H10-$G10=0,"",(AJ10-$G10)/($H10-$G10)))
C11: =IFERROR(IF(INDEX(ITT_ChildProtection_OP_A,MATCH("1.2",ITT_ChildProtection_OP_A,0))="","",INDEX(ITT_ChildProtection_OP_A,MATCH("1.2",ITT_ChildProtection_OP_A,0))),"") -> 1.2 | D11: =IFERROR(IF(INDEX(ITT_ChildProtection_OP_B,MATCH("1.2",ITT_ChildProtection_OP_A,0))="","",INDEX(ITT_ChildProtection_OP_B,MATCH("1.2",ITT_ChildProtection_OP_A,0))),"") | E11: =IFERROR(IF(INDEX(ITT_ChildProtection_OP_E,MATCH("1.2",ITT_ChildProtection_OP_A,0))="","",INDEX(ITT_ChildProtection_OP_E,MATCH("1.2",ITT_ChildProtection_OP_A,0))),"") | F11: =IFERROR(IF(INDEX(ITT_ChildProtection_OP_G,MATCH("1.2",ITT_ChildProtection_OP_A,0))="","",INDEX(ITT_ChildProtection_OP_G,MATCH("1.2",ITT_ChildProtection_OP_A,0))),"") | G11: =IFERROR(IF(INDEX(ITT_ChildProtection_OP_J,MATCH("1.2",ITT_ChildProtection_OP_A,0))="","",INDEX(ITT_ChildProtection_OP_J,MATCH("1.2",ITT_ChildProtection_OP_A,0))),"") | H11: =IFERROR(IF(INDEX(ITT_ChildProtection_OP_K,MATCH("1.2",ITT_ChildProtection_OP_A,0))="","",INDEX(ITT_ChildProtection_OP_K,MATCH("1.2",ITT_ChildProtection_OP_A,0))),"") | M11: =IF(OR(L11="",$G11="",$H11=""),"",IF($H11-$G11=0,"",(L11-$G11)/($H11-$G11))) | S11: =IF(OR(R11="",$G11="",$H11=""),"",IF($H11-$G11=0,"",(R11-$G11)/($H11-$G11))) | Y11: =IF(OR(X11="",$G11="",$H11=""),"",IF($H11-$G11=0,"",(X11-$G11)/($H11-$G11))) | AE11: =IF(OR(AD11="",$G11="",$H11=""),"",IF($H11-$G11=0,"",(AD11-$G11)/($H11-$G11))) | AK11: =IF(OR(AJ11="",$G11="",$H11=""),"",IF($H11-$G11=0,"",(AJ11-$G11)/($H11-$G11)))
C12: =IFERROR(IF(INDEX(ITT_ChildProtection_OP_A,MATCH("1.3",ITT_ChildProtection_OP_A,0))="","",INDEX(ITT_ChildProtection_OP_A,MATCH("1.3",ITT_ChildProtection_OP_A,0))),"") -> 1.3 | D12: =IFERROR(IF(INDEX(ITT_ChildProtection_OP_B,MATCH("1.3",ITT_ChildProtection_OP_A,0))="","",INDEX(ITT_ChildProtection_OP_B,MATCH("1.3",ITT_ChildProtection_OP_A,0))),"") | E12: =IFERROR(IF(INDEX(ITT_ChildProtection_OP_E,MATCH("1.3",ITT_ChildProtection_OP_A,0))="","",INDEX(ITT_ChildProtection_OP_E,MATCH("1.3",ITT_ChildProtection_OP_A,0))),"") | F12: =IFERROR(IF(INDEX(ITT_ChildProtection_OP_G,MATCH("1.3",ITT_ChildProtection_OP_A,0))="","",INDEX(ITT_ChildProtection_OP_G,MATCH("1.3",ITT_ChildProtection_OP_A,0))),"") | G12: =IFERROR(IF(INDEX(ITT_ChildProtection_OP_J,MATCH("1.3",ITT_ChildProtection_OP_A,0))="","",INDEX(ITT_ChildProtection_OP_J,MATCH("1.3",ITT_ChildProtection_OP_A,0))),"") | H12: =IFERROR(IF(INDEX(ITT_ChildProtection_OP_K,MATCH("1.3",ITT_ChildProtection_OP_A,0))="","",INDEX(ITT_ChildProtection_OP_K,MATCH("1.3",ITT_ChildProtection_OP_A,0))),"") | M12: =IF(OR(L12="",$G12="",$H12=""),"",IF($H12-$G12=0,"",(L12-$G12)/($H12-$G12))) | S12: =IF(OR(R12="",$G12="",$H12=""),"",IF($H12-$G12=0,"",(R12-$G12)/($H12-$G12))) | Y12: =IF(OR(X12="",$G12="",$H12=""),"",IF($H12-$G12=0,"",(X12-$G12)/($H12-$G12))) | AE12: =IF(OR(AD12="",$G12="",$H12=""),"",IF($H12-$G12=0,"",(AD12-$G12)/($H12-$G12))) | AK12: =IF(OR(AJ12="",$G12="",$H12=""),"",IF($H12-$G12=0,"",(AJ12-$G12)/($H12-$G12)))
C13: =IFERROR(IF(INDEX(ITT_ChildProtection_OP_A,MATCH("2.1",ITT_ChildProtection_OP_A,0))="","",INDEX(ITT_ChildProtection_OP_A,MATCH("2.1",ITT_ChildProtection_OP_A,0))),"") -> 2.1 | D13: =IFERROR(IF(INDEX(ITT_ChildProtection_OP_B,MATCH("2.1",ITT_ChildProtection_OP_A,0))="","",INDEX(ITT_ChildProtection_OP_B,MATCH("2.1",ITT_ChildProtection_OP_A,0))),"") | E13: =IFERROR(IF(INDEX(ITT_ChildProtection_OP_E,MATCH("2.1",ITT_ChildProtection_OP_A,0))="","",INDEX(ITT_ChildProtection_OP_E,MATCH("2.1",ITT_ChildProtection_OP_A,0))),"") | F13: =IFERROR(IF(INDEX(ITT_ChildProtection_OP_G,MATCH("2.1",ITT_ChildProtection_OP_A,0))="","",INDEX(ITT_ChildProtection_OP_G,MATCH("2.1",ITT_ChildProtection_OP_A,0))),"") | G13: =IFERROR(IF(INDEX(ITT_ChildProtection_OP_J,MATCH("2.1",ITT_ChildProtection_OP_A,0))="","",INDEX(ITT_ChildProtection_OP_J,MATCH("2.1",ITT_ChildProtection_OP_A,0))),"") | H13: =IFERROR(IF(INDEX(ITT_ChildProtection_OP_K,MATCH("2.1",ITT_ChildProtection_OP_A,0))="","",INDEX(ITT_ChildProtection_OP_K,MATCH("2.1",ITT_ChildProtection_OP_A,0))),"") | M13: =IF(OR(L13="",$G13="",$H13=""),"",IF($H13-$G13=0,"",(L13-$G13)/($H13-$G13))) | S13: =IF(OR(R13="",$G13="",$H13=""),"",IF($H13-$G13=0,"",(R13-$G13)/($H13-$G13))) | Y13: =IF(OR(X13="",$G13="",$H13=""),"",IF($H13-$G13=0,"",(X13-$G13)/($H13-$G13))) | AE13: =IF(OR(AD13="",$G13="",$H13=""),"",IF($H13-$G13=0,"",(AD13-$G13)/($H13-$G13))) | AK13: =IF(OR(AJ13="",$G13="",$H13=""),"",IF($H13-$G13=0,"",(AJ13-$G13)/($H13-$G13)))
C14: =IFERROR(IF(INDEX(ITT_ChildProtection_OP_A,MATCH("2.2",ITT_ChildProtection_OP_A,0))="","",INDEX(ITT_ChildProtection_OP_A,MATCH("2.2",ITT_ChildProtection_OP_A,0))),"") -> 2.2 | D14: =IFERROR(IF(INDEX(ITT_ChildProtection_OP_B,MATCH("2.2",ITT_ChildProtection_OP_A,0))="","",INDEX(ITT_ChildProtection_OP_B,MATCH("2.2",ITT_ChildProtection_OP_A,0))),"") | E14: =IFERROR(IF(INDEX(ITT_ChildProtection_OP_E,MATCH("2.2",ITT_ChildProtection_OP_A,0))="","",INDEX(ITT_ChildProtection_OP_E,MATCH("2.2",ITT_ChildProtection_OP_A,0))),"") | F14: =IFERROR(IF(INDEX(ITT_ChildProtection_OP_G,MATCH("2.2",ITT_ChildProtection_OP_A,0))="","",INDEX(ITT_ChildProtection_OP_G,MATCH("2.2",ITT_ChildProtection_OP_A,0))),"") | G14: =IFERROR(IF(INDEX(ITT_ChildProtection_OP_J,MATCH("2.2",ITT_ChildProtection_OP_A,0))="","",INDEX(ITT_ChildProtection_OP_J,MATCH("2.2",ITT_ChildProtection_OP_A,0))),"") | H14: =IFERROR(IF(INDEX(ITT_ChildProtection_OP_K,MATCH("2.2",ITT_ChildProtection_OP_A,0))="","",INDEX(ITT_ChildProtection_OP_K,MATCH("2.2",ITT_ChildProtection_OP_A,0))),"") | M14: =IF(OR(L14="",$G14="",$H14=""),"",IF($H14-$G14=0,"",(L14-$G14)/($H14-$G14))) | S14: =IF(OR(R14="",$G14="",$H14=""),"",IF($H14-$G14=0,"",(R14-$G14)/($H14-$G14))) | Y14: =IF(OR(X14="",$G14="",$H14=""),"",IF($H14-$G14=0,"",(X14-$G14)/($H14-$G14))) | AE14: =IF(OR(AD14="",$G14="",$H14=""),"",IF($H14-$G14=0,"",(AD14-$G14)/($H14-$G14))) | AK14: =IF(OR(AJ14="",$G14="",$H14=""),"",IF($H14-$G14=0,"",(AJ14-$G14)/($H14-$G14)))
C15: =IFERROR(IF(INDEX(ITT_ChildProtection_OP_A,MATCH("2.3",ITT_ChildProtection_OP_A,0))="","",INDEX(ITT_ChildProtection_OP_A,MATCH("2.3",ITT_ChildProtection_OP_A,0))),"") -> 2.3 | D15: =IFERROR(IF(INDEX(ITT_ChildProtection_OP_B,MATCH("2.3",ITT_ChildProtection_OP_A,0))="","",INDEX(ITT_ChildProtection_OP_B,MATCH("2.3",ITT_ChildProtection_OP_A,0))),"") | E15: =IFERROR(IF(INDEX(ITT_ChildProtection_OP_E,MATCH("2.3",ITT_ChildProtection_OP_A,0))="","",INDEX(ITT_ChildProtection_OP_E,MATCH("2.3",ITT_ChildProtection_OP_A,0))),"") | F15: =IFERROR(IF(INDEX(ITT_ChildProtection_OP_G,MATCH("2.3",ITT_ChildProtection_OP_A,0))="","",INDEX(ITT_ChildProtection_OP_G,MATCH("2.3",ITT_ChildProtection_OP_A,0))),"") | G15: =IFERROR(IF(INDEX(ITT_ChildProtection_OP_J,MATCH("2.3",ITT_ChildProtection_OP_A,0))="","",INDEX(ITT_ChildProtection_OP_J,MATCH("2.3",ITT_ChildProtection_OP_A,0))),"") | H15: =IFERROR(IF(INDEX(ITT_ChildProtection_OP_K,MATCH("2.3",ITT_ChildProtection_OP_A,0))="","",INDEX(ITT_ChildProtection_OP_K,MATCH("2.3",ITT_ChildProtection_OP_A,0))),"") | M15: =IF(OR(L15="",$G15="",$H15=""),"",IF($H15-$G15=0,"",(L15-$G15)/($H15-$G15))) | S15: =IF(OR(R15="",$G15="",$H15=""),"",IF($H15-$G15=0,"",(R15-$G15)/($H15-$G15))) | Y15: =IF(OR(X15="",$G15="",$H15=""),"",IF($H15-$G15=0,"",(X15-$G15)/($H15-$G15))) | AE15: =IF(OR(AD15="",$G15="",$H15=""),"",IF($H15-$G15=0,"",(AD15-$G15)/($H15-$G15))) | AK15: =IF(OR(AJ15="",$G15="",$H15=""),"",IF($H15-$G15=0,"",(AJ15-$G15)/($H15-$G15)))
C16: =IFERROR(IF(INDEX(ITT_ChildProtection_OP_A,MATCH("3.1",ITT_ChildProtection_OP_A,0))="","",INDEX(ITT_ChildProtection_OP_A,MATCH("3.1",ITT_ChildProtection_OP_A,0))),"") -> 3.1 | D16: =IFERROR(IF(INDEX(ITT_ChildProtection_OP_B,MATCH("3.1",ITT_ChildProtection_OP_A,0))="","",INDEX(ITT_ChildProtection_OP_B,MATCH("3.1",ITT_ChildProtection_OP_A,0))),"") | E16: =IFERROR(IF(INDEX(ITT_ChildProtection_OP_E,MATCH("3.1",ITT_ChildProtection_OP_A,0))="","",INDEX(ITT_ChildProtection_OP_E,MATCH("3.1",ITT_ChildProtection_OP_A,0))),"") | F16: =IFERROR(IF(INDEX(ITT_ChildProtection_OP_G,MATCH("3.1",ITT_ChildProtection_OP_A,0))="","",INDEX(ITT_ChildProtection_OP_G,MATCH("3.1",ITT_ChildProtection_OP_A,0))),"") | G16: =IFERROR(IF(INDEX(ITT_ChildProtection_OP_J,MATCH("3.1",ITT_ChildProtection_OP_A,0))="","",INDEX(ITT_ChildProtection_OP_J,MATCH("3.1",ITT_ChildProtection_OP_A,0))),"") | H16: =IFERROR(IF(INDEX(ITT_ChildProtection_OP_K,MATCH("3.1",ITT_ChildProtection_OP_A,0))="","",INDEX(ITT_ChildProtection_OP_K,MATCH("3.1",ITT_ChildProtection_OP_A,0))),"") | M16: =IF(OR(L16="",$G16="",$H16=""),"",IF($H16-$G16=0,"",(L16-$G16)/($H16-$G16))) | S16: =IF(OR(R16="",$G16="",$H16=""),"",IF($H16-$G16=0,"",(R16-$G16)/($H16-$G16))) | Y16: =IF(OR(X16="",$G16="",$H16=""),"",IF($H16-$G16=0,"",(X16-$G16)/($H16-$G16))) | AE16: =IF(OR(AD16="",$G16="",$H16=""),"",IF($H16-$G16=0,"",(AD16-$G16)/($H16-$G16))) | AK16: =IF(OR(AJ16="",$G16="",$H16=""),"",IF($H16-$G16=0,"",(AJ16-$G16)/($H16-$G16)))
C17: =IFERROR(IF(INDEX(ITT_ChildProtection_OP_A,MATCH("3.2",ITT_ChildProtection_OP_A,0))="","",INDEX(ITT_ChildProtection_OP_A,MATCH("3.2",ITT_ChildProtection_OP_A,0))),"") -> 3.2 | D17: =IFERROR(IF(INDEX(ITT_ChildProtection_OP_B,MATCH("3.2",ITT_ChildProtection_OP_A,0))="","",INDEX(ITT_ChildProtection_OP_B,MATCH("3.2",ITT_ChildProtection_OP_A,0))),"") | E17: =IFERROR(IF(INDEX(ITT_ChildProtection_OP_E,MATCH("3.2",ITT_ChildProtection_OP_A,0))="","",INDEX(ITT_ChildProtection_OP_E,MATCH("3.2",ITT_ChildProtection_OP_A,0))),"") | F17: =IFERROR(IF(INDEX(ITT_ChildProtection_OP_G,MATCH("3.2",ITT_ChildProtection_OP_A,0))="","",INDEX(ITT_ChildProtection_OP_G,MATCH("3.2",ITT_ChildProtection_OP_A,0))),"") | G17: =IFERROR(IF(INDEX(ITT_ChildProtection_OP_J,MATCH("3.2",ITT_ChildProtection_OP_A,0))="","",INDEX(ITT_ChildProtection_OP_J,MATCH("3.2",ITT_ChildProtection_OP_A,0))),"") | H17: =IFERROR(IF(INDEX(ITT_ChildProtection_OP_K,MATCH("3.2",ITT_ChildProtection_OP_A,0))="","",INDEX(ITT_ChildProtection_OP_K,MATCH("3.2",ITT_ChildProtection_OP_A,0))),"") | M17: =IF(OR(L17="",$G17="",$H17=""),"",IF($H17-$G17=0,"",(L17-$G17)/($H17-$G17))) | S17: =IF(OR(R17="",$G17="",$H17=""),"",IF($H17-$G17=0,"",(R17-$G17)/($H17-$G17))) | Y17: =IF(OR(X17="",$G17="",$H17=""),"",IF($H17-$G17=0,"",(X17-$G17)/($H17-$G17))) | AE17: =IF(OR(AD17="",$G17="",$H17=""),"",IF($H17-$G17=0,"",(AD17-$G17)/($H17-$G17))) | AK17: =IF(OR(AJ17="",$G17="",$H17=""),"",IF($H17-$G17=0,"",(AJ17-$G17)/($H17-$G17)))
C18: =IFERROR(IF(INDEX(ITT_ChildProtection_OP_A,MATCH("3.3",ITT_ChildProtection_OP_A,0))="","",INDEX(ITT_ChildProtection_OP_A,MATCH("3.3",ITT_ChildProtection_OP_A,0))),"") -> 3.3 | D18: =IFERROR(IF(INDEX(ITT_ChildProtection_OP_B,MATCH("3.3",ITT_ChildProtection_OP_A,0))="","",INDEX(ITT_ChildProtection_OP_B,MATCH("3.3",ITT_ChildProtection_OP_A,0))),"") | E18: =IFERROR(IF(INDEX(ITT_ChildProtection_OP_E,MATCH("3.3",ITT_ChildProtection_OP_A,0))="","",INDEX(ITT_ChildProtection_OP_E,MATCH("3.3",ITT_ChildProtection_OP_A,0))),"") | F18: =IFERROR(IF(INDEX(ITT_ChildProtection_OP_G,MATCH("3.3",ITT_ChildProtection_OP_A,0))="","",INDEX(ITT_ChildProtection_OP_G,MATCH("3.3",ITT_ChildProtection_OP_A,0))),"") | G18: =IFERROR(IF(INDEX(ITT_ChildProtection_OP_J,MATCH("3.3",ITT_ChildProtection_OP_A,0))="","",INDEX(ITT_ChildProtection_OP_J,MATCH("3.3",ITT_ChildProtection_OP_A,0))),"") | H18: =IFERROR(IF(INDEX(ITT_ChildProtection_OP_K,MATCH("3.3",ITT_ChildProtection_OP_A,0))="","",INDEX(ITT_ChildProtection_OP_K,MATCH("3.3",ITT_ChildProtection_OP_A,0))),"") | M18: =IF(OR(L18="",$G18="",$H18=""),"",IF($H18-$G18=0,"",(L18-$G18)/($H18-$G18))) | S18: =IF(OR(R18="",$G18="",$H18=""),"",IF($H18-$G18=0,"",(R18-$G18)/($H18-$G18))) | Y18: =IF(OR(X18="",$G18="",$H18=""),"",IF($H18-$G18=0,"",(X18-$G18)/($H18-$G18))) | AE18: =IF(OR(AD18="",$G18="",$H18=""),"",IF($H18-$G18=0,"",(AD18-$G18)/($H18-$G18))) | AK18: =IF(OR(AJ18="",$G18="",$H18=""),"",IF($H18-$G18=0,"",(AJ18-$G18)/($H18-$G18)))
C19: =IFERROR(IF(INDEX(ITT_ChildProtection_OP_A,MATCH("4.1",ITT_ChildProtection_OP_A,0))="","",INDEX(ITT_ChildProtection_OP_A,MATCH("4.1",ITT_ChildProtection_OP_A,0))),"") -> 4.1 | D19: =IFERROR(IF(INDEX(ITT_ChildProtection_OP_B,MATCH("4.1",ITT_ChildProtection_OP_A,0))="","",INDEX(ITT_ChildProtection_OP_B,MATCH("4.1",ITT_ChildProtection_OP_A,0))),"") | E19: =IFERROR(IF(INDEX(ITT_ChildProtection_OP_E,MATCH("4.1",ITT_ChildProtection_OP_A,0))="","",INDEX(ITT_ChildProtection_OP_E,MATCH("4.1",ITT_ChildProtection_OP_A,0))),"") | F19: =IFERROR(IF(INDEX(ITT_ChildProtection_OP_G,MATCH("4.1",ITT_ChildProtection_OP_A,0))="","",INDEX(ITT_ChildProtection_OP_G,MATCH("4.1",ITT_ChildProtection_OP_A,0))),"") | G19: =IFERROR(IF(INDEX(ITT_ChildProtection_OP_J,MATCH("4.1",ITT_ChildProtection_OP_A,0))="","",INDEX(ITT_ChildProtection_OP_J,MATCH("4.1",ITT_ChildProtection_OP_A,0))),"") | H19: =IFERROR(IF(INDEX(ITT_ChildProtection_OP_K,MATCH("4.1",ITT_ChildProtection_OP_A,0))="","",INDEX(ITT_ChildProtection_OP_K,MATCH("4.1",ITT_ChildProtection_OP_A,0))),"") | M19: =IF(OR(L19="",$G19="",$H19=""),"",IF($H19-$G19=0,"",(L19-$G19)/($H19-$G19))) | S19: =IF(OR(R19="",$G19="",$H19=""),"",IF($H19-$G19=0,"",(R19-$G19)/($H19-$G19))) | Y19: =IF(OR(X19="",$G19="",$H19=""),"",IF($H19-$G19=0,"",(X19-$G19)/($H19-$G19))) | AE19: =IF(OR(AD19="",$G19="",$H19=""),"",IF($H19-$G19=0,"",(AD19-$G19)/($H19-$G19))) | AK19: =IF(OR(AJ19="",$G19="",$H19=""),"",IF($H19-$G19=0,"",(AJ19-$G19)/($H19-$G19)))
C20: =IFERROR(IF(INDEX(ITT_ChildProtection_OP_A,MATCH("4.2",ITT_ChildProtection_OP_A,0))="","",INDEX(ITT_ChildProtection_OP_A,MATCH("4.2",ITT_ChildProtection_OP_A,0))),"") -> 4.2 | D20: =IFERROR(IF(INDEX(ITT_ChildProtection_OP_B,MATCH("4.2",ITT_ChildProtection_OP_A,0))="","",INDEX(ITT_ChildProtection_OP_B,MATCH("4.2",ITT_ChildProtection_OP_A,0))),"") | E20: =IFERROR(IF(INDEX(ITT_ChildProtection_OP_E,MATCH("4.2",ITT_ChildProtection_OP_A,0))="","",INDEX(ITT_ChildProtection_OP_E,MATCH("4.2",ITT_ChildProtection_OP_A,0))),"") | F20: =IFERROR(IF(INDEX(ITT_ChildProtection_OP_G,MATCH("4.2",ITT_ChildProtection_OP_A,0))="","",INDEX(ITT_ChildProtection_OP_G,MATCH("4.2",ITT_ChildProtection_OP_A,0))),"") | G20: =IFERROR(IF(INDEX(ITT_ChildProtection_OP_J,MATCH("4.2",ITT_ChildProtection_OP_A,0))="","",INDEX(ITT_ChildProtection_OP_J,MATCH("4.2",ITT_ChildProtection_OP_A,0))),"") | H20: =IFERROR(IF(INDEX(ITT_ChildProtection_OP_K,MATCH("4.2",ITT_ChildProtection_OP_A,0))="","",INDEX(ITT_ChildProtection_OP_K,MATCH("4.2",ITT_ChildProtection_OP_A,0))),"") | M20: =IF(OR(L20="",$G20="",$H20=""),"",IF($H20-$G20=0,"",(L20-$G20)/($H20-$G20))) | S20: =IF(OR(R20="",$G20="",$H20=""),"",IF($H20-$G20=0,"",(R20-$G20)/($H20-$G20))) | Y20: =IF(OR(X20="",$G20="",$H20=""),"",IF($H20-$G20=0,"",(X20-$G20)/($H20-$G20))) | AE20: =IF(OR(AD20="",$G20="",$H20=""),"",IF($H20-$G20=0,"",(AD20-$G20)/($H20-$G20))) | AK20: =IF(OR(AJ20="",$G20="",$H20=""),"",IF($H20-$G20=0,"",(AJ20-$G20)/($H20-$G20)))
C21: =IFERROR(IF(INDEX(ITT_ChildProtection_OP_A,MATCH("4.3",ITT_ChildProtection_OP_A,0))="","",INDEX(ITT_ChildProtection_OP_A,MATCH("4.3",ITT_ChildProtection_OP_A,0))),"") -> 4.3 | D21: =IFERROR(IF(INDEX(ITT_ChildProtection_OP_B,MATCH("4.3",ITT_ChildProtection_OP_A,0))="","",INDEX(ITT_ChildProtection_OP_B,MATCH("4.3",ITT_ChildProtection_OP_A,0))),"") | E21: =IFERROR(IF(INDEX(ITT_ChildProtection_OP_E,MATCH("4.3",ITT_ChildProtection_OP_A,0))="","",INDEX(ITT_ChildProtection_OP_E,MATCH("4.3",ITT_ChildProtection_OP_A,0))),"") | F21: =IFERROR(IF(INDEX(ITT_ChildProtection_OP_G,MATCH("4.3",ITT_ChildProtection_OP_A,0))="","",INDEX(ITT_ChildProtection_OP_G,MATCH("4.3",ITT_ChildProtection_OP_A,0))),"") | G21: =IFERROR(IF(INDEX(ITT_ChildProtection_OP_J,MATCH("4.3",ITT_ChildProtection_OP_A,0))="","",INDEX(ITT_ChildProtection_OP_J,MATCH("4.3",ITT_ChildProtection_OP_A,0))),"") | H21: =IFERROR(IF(INDEX(ITT_ChildProtection_OP_K,MATCH("4.3",ITT_ChildProtection_OP_A,0))="","",INDEX(ITT_ChildProtection_OP_K,MATCH("4.3",ITT_ChildProtection_OP_A,0))),"") | M21: =IF(OR(L21="",$G21="",$H21=""),"",IF($H21-$G21=0,"",(L21-$G21)/($H21-$G21))) | S21: =IF(OR(R21="",$G21="",$H21=""),"",IF($H21-$G21=0,"",(R21-$G21)/($H21-$G21))) | Y21: =IF(OR(X21="",$G21="",$H21=""),"",IF($H21-$G21=0,"",(X21-$G21)/($H21-$G21))) | AE21: =IF(OR(AD21="",$G21="",$H21=""),"",IF($H21-$G21=0,"",(AD21-$G21)/($H21-$G21))) | AK21: =IF(OR(AJ21="",$G21="",$H21=""),"",IF($H21-$G21=0,"",(AJ21-$G21)/($H21-$G21)))
C22: =IFERROR(IF(INDEX(ITT_ChildProtection_OP_A,MATCH("5.1",ITT_ChildProtection_OP_A,0))="","",INDEX(ITT_ChildProtection_OP_A,MATCH("5.1",ITT_ChildProtection_OP_A,0))),"") -> 5.1 | D22: =IFERROR(IF(INDEX(ITT_ChildProtection_OP_B,MATCH("5.1",ITT_ChildProtection_OP_A,0))="","",INDEX(ITT_ChildProtection_OP_B,MATCH("5.1",ITT_ChildProtection_OP_A,0))),"") | E22: =IFERROR(IF(INDEX(ITT_ChildProtection_OP_E,MATCH("5.1",ITT_ChildProtection_OP_A,0))="","",INDEX(ITT_ChildProtection_OP_E,MATCH("5.1",ITT_ChildProtection_OP_A,0))),"") | F22: =IFERROR(IF(INDEX(ITT_ChildProtection_OP_G,MATCH("5.1",ITT_ChildProtection_OP_A,0))="","",INDEX(ITT_ChildProtection_OP_G,MATCH("5.1",ITT_ChildProtection_OP_A,0))),"") | G22: =IFERROR(IF(INDEX(ITT_ChildProtection_OP_J,MATCH("5.1",ITT_ChildProtection_OP_A,0))="","",INDEX(ITT_ChildProtection_OP_J,MATCH("5.1",ITT_ChildProtection_OP_A,0))),"") | H22: =IFERROR(IF(INDEX(ITT_ChildProtection_OP_K,MATCH("5.1",ITT_ChildProtection_OP_A,0))="","",INDEX(ITT_ChildProtection_OP_K,MATCH("5.1",ITT_ChildProtection_OP_A,0))),"") | M22: =IF(OR(L22="",$G22="",$H22=""),"",IF($H22-$G22=0,"",(L22-$G22)/($H22-$G22))) | S22: =IF(OR(R22="",$G22="",$H22=""),"",IF($H22-$G22=0,"",(R22-$G22)/($H22-$G22))) | Y22: =IF(OR(X22="",$G22="",$H22=""),"",IF($H22-$G22=0,"",(X22-$G22)/($H22-$G22))) | AE22: =IF(OR(AD22="",$G22="",$H22=""),"",IF($H22-$G22=0,"",(AD22-$G22)/($H22-$G22))) | AK22: =IF(OR(AJ22="",$G22="",$H22=""),"",IF($H22-$G22=0,"",(AJ22-$G22)/($H22-$G22)))
C23: =IFERROR(IF(INDEX(ITT_ChildProtection_OP_A,MATCH("5.2",ITT_ChildProtection_OP_A,0))="","",INDEX(ITT_ChildProtection_OP_A,MATCH("5.2",ITT_ChildProtection_OP_A,0))),"") -> 5.2 | D23: =IFERROR(IF(INDEX(ITT_ChildProtection_OP_B,MATCH("5.2",ITT_ChildProtection_OP_A,0))="","",INDEX(ITT_ChildProtection_OP_B,MATCH("5.2",ITT_ChildProtection_OP_A,0))),"") | E23: =IFERROR(IF(INDEX(ITT_ChildProtection_OP_E,MATCH("5.2",ITT_ChildProtection_OP_A,0))="","",INDEX(ITT_ChildProtection_OP_E,MATCH("5.2",ITT_ChildProtection_OP_A,0))),"") | F23: =IFERROR(IF(INDEX(ITT_ChildProtection_OP_G,MATCH("5.2",ITT_ChildProtection_OP_A,0))="","",INDEX(ITT_ChildProtection_OP_G,MATCH("5.2",ITT_ChildProtection_OP_A,0))),"") | G23: =IFERROR(IF(INDEX(ITT_ChildProtection_OP_J,MATCH("5.2",ITT_ChildProtection_OP_A,0))="","",INDEX(ITT_ChildProtection_OP_J,MATCH("5.2",ITT_ChildProtection_OP_A,0))),"") | H23: =IFERROR(IF(INDEX(ITT_ChildProtection_OP_K,MATCH("5.2",ITT_ChildProtection_OP_A,0))="","",INDEX(ITT_ChildProtection_OP_K,MATCH("5.2",ITT_ChildProtection_OP_A,0))),"") | M23: =IF(OR(L23="",$G23="",$H23=""),"",IF($H23-$G23=0,"",(L23-$G23)/($H23-$G23))) | S23: =IF(OR(R23="",$G23="",$H23=""),"",IF($H23-$G23=0,"",(R23-$G23)/($H23-$G23))) | Y23: =IF(OR(X23="",$G23="",$H23=""),"",IF($H23-$G23=0,"",(X23-$G23)/($H23-$G23))) | AE23: =IF(OR(AD23="",$G23="",$H23=""),"",IF($H23-$G23=0,"",(AD23-$G23)/($H23-$G23))) | AK23: =IF(OR(AJ23="",$G23="",$H23=""),"",IF($H23-$G23=0,"",(AJ23-$G23)/($H23-$G23)))
C24: =IFERROR(IF(INDEX(ITT_ChildProtection_OP_A,MATCH("5.3",ITT_ChildProtection_OP_A,0))="","",INDEX(ITT_ChildProtection_OP_A,MATCH("5.3",ITT_ChildProtection_OP_A,0))),"") -> 5.3 | D24: =IFERROR(IF(INDEX(ITT_ChildProtection_OP_B,MATCH("5.3",ITT_ChildProtection_OP_A,0))="","",INDEX(ITT_ChildProtection_OP_B,MATCH("5.3",ITT_ChildProtection_OP_A,0))),"") | E24: =IFERROR(IF(INDEX(ITT_ChildProtection_OP_E,MATCH("5.3",ITT_ChildProtection_OP_A,0))="","",INDEX(ITT_ChildProtection_OP_E,MATCH("5.3",ITT_ChildProtection_OP_A,0))),"") | F24: =IFERROR(IF(INDEX(ITT_ChildProtection_OP_G,MATCH("5.3",ITT_ChildProtection_OP_A,0))="","",INDEX(ITT_ChildProtection_OP_G,MATCH("5.3",ITT_ChildProtection_OP_A,0))),"") | G24: =IFERROR(IF(INDEX(ITT_ChildProtection_OP_J,MATCH("5.3",ITT_ChildProtection_OP_A,0))="","",INDEX(ITT_ChildProtection_OP_J,MATCH("5.3",ITT_ChildProtection_OP_A,0))),"") | H24: =IFERROR(IF(INDEX(ITT_ChildProtection_OP_K,MATCH("5.3",ITT_ChildProtection_OP_A,0))="","",INDEX(ITT_ChildProtection_OP_K,MATCH("5.3",ITT_ChildProtection_OP_A,0))),"") | M24: =IF(OR(L24="",$G24="",$H24=""),"",IF($H24-$G24=0,"",(L24-$G24)/($H24-$G24))) | S24: =IF(OR(R24="",$G24="",$H24=""),"",IF($H24-$G24=0,"",(R24-$G24)/($H24-$G24))) | Y24: =IF(OR(X24="",$G24="",$H24=""),"",IF($H24-$G24=0,"",(X24-$G24)/($H24-$G24))) | AE24: =IF(OR(AD24="",$G24="",$H24=""),"",IF($H24-$G24=0,"",(AD24-$G24)/($H24-$G24))) | AK24: =IF(OR(AJ24="",$G24="",$H24=""),"",IF($H24-$G24=0,"",(AJ24-$G24)/($H24-$G24)))
